<?xml version="1.0" ?>
<!-- =================================================================================== -->
<!-- |    This document was autogenerated by xacro from rosbot_xl_manipulation.urdf.xacro | -->
<!-- |    EDITING THIS FILE BY HAND IS NOT RECOMMENDED                                 | -->
<!-- =================================================================================== -->
<robot name="rosbot_xl">
  <link name="base_link"/>
  <joint name="base_to_body_joint" type="fixed">
    <origin rpy="0.0 0.0 0.0" xyz="0.0 0.0 0.048"/>
    <parent link="base_link"/>
    <child link="body_link"/>
  </joint>
  <link name="body_link">
    <visual>
      <geometry>
        <mesh filename="http://{{.Host}}:{{env "FOXGLOVE_PORT"}}/ros2_ws/install/rosbot_xl_description/share/rosbot_xl_description/meshes/body.dae" scale="1 1 1"/>
      </geometry>
      <origin rpy="0.0 0.0 0.0" xyz="0.0 0.0 0.0"/>
    </visual>
    <collision>
      <geometry>
        <mesh filename="http://{{.Host}}:{{env "FOXGLOVE_PORT"}}/ros2_ws/install/rosbot_xl_description/share/rosbot_xl_description/meshes/body_colision.stl" scale="1 1 1"/>
      </geometry>
      <origin rpy="0.0 0.0 0.0" xyz="0.0 0.0 0.0"/>
    </collision>
    <inertial>
      <mass value="3.5"/>
      <origin rpy="0.0 0.0 0.0" xyz="0.0 0.0 0.0358"/>
      <inertia ixx="0.01393" ixy="-0.000020968097" ixz="0.000010399694" iyy="0.01081" iyz="0.000059372953" izz="0.02048"/>
    </inertial>
  </link>
  <joint name="body_to_cover_joint" type="fixed">
    <origin rpy="0.0 0.0 0.0" xyz="0.0 0.0 0.08345"/>
    <parent link="body_link"/>
    <child link="cover_link"/>
  </joint>
  <link name="cover_link"/>
  <joint name="body_to_imu_joint" type="fixed">
    <origin rpy="3.14159 0.0 0.0" xyz="-0.1369 -0.0419 0.0370"/>
    <parent link="body_link"/>
    <child link="imu_link"/>
  </joint>
  <link name="imu_link"/>
  <joint name="fl_wheel_joint" type="continuous">
    <parent link="body_link"/>
    <child link="fl_wheel_link"/>
    <origin rpy="0.0 0.0 0.0" xyz="0.085 0.124 0.0"/>
    <axis xyz="0.0 1.0 0.0"/>
    <limit effort="1.27" velocity="21.0"/>
    <dynamics damping="0.001" friction="0.001"/>
  </joint>
  <link name="fl_wheel_link">
    <visual>
      <geometry>
        <mesh filename="http://{{.Host}}:{{env "FOXGLOVE_PORT"}}/ros2_ws/install/rosbot_xl_description/share/rosbot_xl_description/meshes/wheel_b.dae" scale="1 1 1"/>
      </geometry>
      <origin rpy="0.0 0.0 3.141592653589793" xyz="0.0 0.0 0.0"/>
    </visual>
    <collision>
      <geometry>
        <cylinder length="0.036" radius="0.048"/>
      </geometry>
      <origin rpy="1.5707963267948966 0.0 0.0" xyz="0.0 0.0 0.0"/>
    </collision>
    <inertial>
      <mass value="0.051"/>
      <inertia ixx="5.0587413e-05" ixy="0.0" ixz="0.0" iyy="8.5933192e-05" iyz="0.0" izz="5.0587829e-05"/>
    </inertial>
  </link>
  <joint name="fr_wheel_joint" type="continuous">
    <parent link="body_link"/>
    <child link="fr_wheel_link"/>
    <origin rpy="0.0 0.0 0.0" xyz="0.085 -0.124 0.0"/>
    <axis xyz="0.0 1.0 0.0"/>
    <limit effort="1.27" velocity="21.0"/>
    <dynamics damping="0.001" friction="0.001"/>
  </joint>
  <link name="fr_wheel_link">
    <visual>
      <geometry>
        <mesh filename="http://{{.Host}}:{{env "FOXGLOVE_PORT"}}/ros2_ws/install/rosbot_xl_description/share/rosbot_xl_description/meshes/wheel_a.dae" scale="1 1 1"/>
      </geometry>
      <origin rpy="0.0 0.0 3.141592653589793" xyz="0.0 0.0 0.0"/>
    </visual>
    <collision>
      <geometry>
        <cylinder length="0.036" radius="0.048"/>
      </geometry>
      <origin rpy="1.5707963267948966 0.0 0.0" xyz="0.0 0.0 0.0"/>
    </collision>
    <inertial>
      <mass value="0.051"/>
      <inertia ixx="5.0587413e-05" ixy="0.0" ixz="0.0" iyy="8.5933192e-05" iyz="0.0" izz="5.0587829e-05"/>
    </inertial>
  </link>
  <joint name="rl_wheel_joint" type="continuous">
    <parent link="body_link"/>
    <child link="rl_wheel_link"/>
    <origin rpy="0.0 0.0 0.0" xyz="-0.085 0.124 0.0"/>
    <axis xyz="0.0 1.0 0.0"/>
    <limit effort="1.27" velocity="21.0"/>
    <dynamics damping="0.001" friction="0.001"/>
  </joint>
  <link name="rl_wheel_link">
    <visual>
      <geometry>
        <mesh filename="http://{{.Host}}:{{env "FOXGLOVE_PORT"}}/ros2_ws/install/rosbot_xl_description/share/rosbot_xl_description/meshes/wheel_a.dae" scale="1 1 1"/>
      </geometry>
      <origin rpy="0.0 0.0 0.0" xyz="0.0 0.0 0.0"/>
    </visual>
    <collision>
      <geometry>
        <cylinder length="0.036" radius="0.048"/>
      </geometry>
      <origin rpy="1.5707963267948966 0.0 0.0" xyz="0.0 0.0 0.0"/>
    </collision>
    <inertial>
      <mass value="0.051"/>
      <inertia ixx="5.0587413e-05" ixy="0.0" ixz="0.0" iyy="8.5933192e-05" iyz="0.0" izz="5.0587829e-05"/>
    </inertial>
  </link>
  <joint name="rr_wheel_joint" type="continuous">
    <parent link="body_link"/>
    <child link="rr_wheel_link"/>
    <origin rpy="0.0 0.0 0.0" xyz="-0.085 -0.124 0.0"/>
    <axis xyz="0.0 1.0 0.0"/>
    <limit effort="1.27" velocity="21.0"/>
    <dynamics damping="0.001" friction="0.001"/>
  </joint>
  <link name="rr_wheel_link">
    <visual>
      <geometry>
        <mesh filename="http://{{.Host}}:{{env "FOXGLOVE_PORT"}}/ros2_ws/install/rosbot_xl_description/share/rosbot_xl_description/meshes/wheel_b.dae" scale="1 1 1"/>
      </geometry>
      <origin rpy="0.0 0.0 0.0" xyz="0.0 0.0 0.0"/>
    </visual>
    <collision>
      <geometry>
        <cylinder length="0.036" radius="0.048"/>
      </geometry>
      <origin rpy="1.5707963267948966 0.0 0.0" xyz="0.0 0.0 0.0"/>
    </collision>
    <inertial>
      <mass value="0.051"/>
      <inertia ixx="5.0587413e-05" ixy="0.0" ixz="0.0" iyy="8.5933192e-05" iyz="0.0" izz="5.0587829e-05"/>
    </inertial>
  </link>
  <ros2_control name="imu" type="sensor">
    <hardware>
      <plugin>rosbot_hardware_interfaces/RosbotImuSensor</plugin>
      <param name="connection_timeout_ms">120000</param>
      <param name="connection_check_period_ms">500</param>
    </hardware>
    <sensor name="imu">
      <state_interface name="orientation.x"/>
      <state_interface name="orientation.y"/>
      <state_interface name="orientation.z"/>
      <state_interface name="orientation.w"/>
      <state_interface name="angular_velocity.x"/>
      <state_interface name="angular_velocity.y"/>
      <state_interface name="angular_velocity.z"/>
      <state_interface name="linear_acceleration.x"/>
      <state_interface name="linear_acceleration.y"/>
      <state_interface name="linear_acceleration.z"/>
    </sensor>
  </ros2_control>
  <ros2_control name="wheels" type="system">
    <hardware>
      <plugin>rosbot_hardware_interfaces/RosbotSystem</plugin>
      <param name="connection_timeout_ms">120000</param>
      <param name="connection_check_period_ms">500</param>
      <!-- order of velocity commands to be published in motors_cmd Float32MultiArray msg -->
      <param name="velocity_command_joint_order">
            rr_wheel_joint,
            rl_wheel_joint,
            fr_wheel_joint,
            fl_wheel_joint
          </param>
    </hardware>
    <joint name="fl_wheel_joint">
      <command_interface name="velocity"/>
      <state_interface name="position"/>
      <state_interface name="velocity"/>
    </joint>
    <joint name="fr_wheel_joint">
      <command_interface name="velocity"/>
      <state_interface name="position"/>
      <state_interface name="velocity"/>
    </joint>
    <joint name="rl_wheel_joint">
      <command_interface name="velocity"/>
      <state_interface name="position"/>
      <state_interface name="velocity"/>
    </joint>
    <joint name="rr_wheel_joint">
      <command_interface name="velocity"/>
      <state_interface name="position"/>
      <state_interface name="velocity"/>
    </joint>
  </ros2_control>
  <joint name="body_to_antenna_connector_joint" type="fixed">
    <origin rpy="0.0 0.0 0.0" xyz="-0.155 -0.055 0.065"/>
    <parent link="body_link"/>
    <child link="antenna_connector_link"/>
  </joint>
  <link name="antenna_connector_link">
    <visual>
      <geometry>
        <mesh filename="http://{{.Host}}:{{env "FOXGLOVE_PORT"}}/ros2_ws/install/rosbot_xl_description/share/rosbot_xl_description/meshes/components/antenna_connector.dae" scale="1 1 1"/>
      </geometry>
      <origin rpy="0.0 0.0 0.0" xyz="0.0 0.0 0.0"/>
    </visual>
  </link>
  <joint name="antenna_connector_to_antenna_joint" type="fixed">
    <origin rpy="0.0 0.0 0.0" xyz="-0.013 0.0 0.008"/>
    <parent link="antenna_connector_link"/>
    <child link="antenna_link"/>
  </joint>
  <link name="antenna_link">
    <visual>
      <geometry>
        <mesh filename="http://{{.Host}}:{{env "FOXGLOVE_PORT"}}/ros2_ws/install/rosbot_xl_description/share/rosbot_xl_description/meshes/components/antenna.dae" scale="1 1 1"/>
      </geometry>
      <origin rpy="0.0 0.0 0.0" xyz="0.0 0.0 0.0"/>
    </visual>
    <collision>
      <geometry>
        <cylinder length="0.1" radius="0.0052"/>
      </geometry>
      <origin rpy="0.0 0.0 0.0" xyz="0.0 0.0 0.05"/>
    </collision>
  </link>
  <joint name="cover_to_slamtec_rplidar_s1_joint" type="fixed">
    <origin rpy="0.0 0.0 0.0" xyz="0.0 0.0 0.0"/>
    <parent link="cover_link"/>
    <child link="slamtec_rplidar_s1_link"/>
  </joint>
  <link name="slamtec_rplidar_s1_link">
    <visual>
      <origin rpy="0.0 0.0 0.0" xyz="0.0 0.0 0.0"/>
      <geometry>
        <mesh filename="http://{{.Host}}:{{env "FOXGLOVE_PORT"}}/ros2_ws/install/ros_components_description/share/ros_components_description/meshes/slamtec_rplidar_s1.dae"/>
      </geometry>
    </visual>
    <!-- spinning head collision -->
    <collision>
      <origin rpy="0.0 0.0 0.0" xyz="0.0 0.0 0.0255"/>
      <geometry>
        <cylinder length="0.051" radius="0.02775"/>
      </geometry>
    </collision>
    <!-- base collision -->
    <collision>
      <origin rpy="0.0 0.0 0.0" xyz="0.0 0.0 0.00975"/>
      <geometry>
        <box size="0.0555 0.0555 0.0195"/>
      </geometry>
    </collision>
    <inertial>
      <origin rpy="0.0 0.0 0.0" xyz="0.0 0.0 0.02775"/>
      <mass value="0.105"/>
      <inertia ixx="0.000049654" ixy="0.0" ixz="0.0" iyy="0.000049654" iyz="0.0" izz="0.000053884"/>
    </inertial>
  </link>
  <joint name="slamtec_rplidar_s1_to_laser_joint" type="fixed">
    <origin rpy="0.0 0.0 3.141592653589793" xyz="0.0 0.0 0.04"/>
    <parent link="slamtec_rplidar_s1_link"/>
    <child link="laser"/>
  </joint>
  <link name="laser"/>
  <gazebo reference="laser">
    <sensor name="rplidar_s1_sensor" type="gpu_lidar">
      <topic>scan</topic>
      <frame_id>laser</frame_id>
      <ignition_frame_id>laser</ignition_frame_id>
      <update_rate>10.0</update_rate>
      <ray>
        <scan>
          <horizontal>
            <samples>920</samples>
            <resolution>1</resolution>
            <min_angle>-3.141592653589793</min_angle>
            <max_angle>3.141592653589793</max_angle>
          </horizontal>
        </scan>
        <range>
          <min>0.04</min>
          <max>40.0</max>
          <resolution>0.03</resolution>
        </range>
        <noise>
          <type>gaussian</type>
          <mean>0.0</mean>
          <stddev>0.001</stddev>
        </noise>
      </ray>
      <always_on>1</always_on>
      <visualize>false</visualize>
    </sensor>
  </gazebo>
  <gazebo>
    <plugin filename="libignition-gazebo-sensors-system.so" name="ignition::gazebo::systems::Sensors">
      <render_engine>ogre2</render_engine>
    </plugin>
  </gazebo>
  <!-- use_gpu has to be set to true, CPU lidar doesn't work in ignition -
  https://github.com/gazebosim/gz-sensors/issues/26 -->
  <!-- collision_enabled parameter added due to collisions using visual meshes, which are very
    heavy and slow down simulation, this parameter allows to easily disable them -->
  <material name="grey">
    <color rgba="0.05 0.05 0.05 1.0"/>
  </material>
  <joint name="cover_link_to_link1" type="fixed">
    <origin rpy="0.0 0.0 0.0" xyz="-0.122 0.0 0.0"/>
    <parent link="cover_link"/>
    <child link="link1"/>
  </joint>
  <link name="link1">
    <visual>
      <origin rpy="0.0 0.0 0.0" xyz="0.0 0.0 0.0"/>
      <geometry>
        <mesh filename="http://{{.Host}}:{{env "FOXGLOVE_PORT"}}/ros2_ws/install/open_manipulator_x_description/share/open_manipulator_x_description/meshes/link1.stl" scale="0.001 0.001 0.001"/>
      </geometry>
      <material name="grey"/>
    </visual>
    <collision>
      <origin rpy="0.0 0.0 0.0" xyz="0.0 0.0 0.0"/>
      <geometry>
        <mesh filename="http://{{.Host}}:{{env "FOXGLOVE_PORT"}}/ros2_ws/install/open_manipulator_x_description/share/open_manipulator_x_description/meshes/link1.stl" scale="0.001 0.001 0.001"/>
      </geometry>
    </collision>
    <inertial>
      <origin xyz="3.0876154e-04 0.0000000e+00 -1.2176461e-04"/>
      <mass value="7.9119962e-02"/>
      <inertia ixx="1.2505234e-05" ixy="0.0" ixz="-1.7855208e-07" iyy="2.1898364e-05" iyz="0.0" izz="1.9267361e-05"/>
    </inertial>
  </link>
  <joint name="joint1" type="revolute">
    <parent link="link1"/>
    <child link="link2"/>
    <origin rpy="0.0 0.0 0.0" xyz="0.012 0.0 0.017"/>
    <axis xyz="0 0 1"/>
    <!-- Joint1 motion is limited only by length of the cable -->
    <limit effort="1" lower="-2.356" upper="5.934" velocity="4.8"/>
    <dynamics damping="0.1"/>
  </joint>
  <link name="link2">
    <visual>
      <origin rpy="0.0 0.0 0.0" xyz="0.0 0.0 0.019"/>
      <geometry>
        <mesh filename="http://{{.Host}}:{{env "FOXGLOVE_PORT"}}/ros2_ws/install/open_manipulator_x_description/share/open_manipulator_x_description/meshes/link2.stl" scale="0.001 0.001 0.001"/>
      </geometry>
      <material name="grey"/>
    </visual>
    <collision>
      <origin rpy="0.0 0.0 0.0" xyz="0.0 0.0 0.019"/>
      <geometry>
        <mesh filename="http://{{.Host}}:{{env "FOXGLOVE_PORT"}}/ros2_ws/install/open_manipulator_x_description/share/open_manipulator_x_description/meshes/link2.stl" scale="0.001 0.001 0.001"/>
      </geometry>
    </collision>
    <inertial>
      <origin xyz="-3.0184870e-04 5.4043684e-04 0.047433463999999995"/>
      <mass value="9.8406837e-02"/>
      <inertia ixx="3.4543422e-05" ixy="-1.6031095e-08" ixz="-3.8375155e-07" iyy="3.2689329e-05" iyz="2.8511935e-08" izz="1.8850320e-05"/>
    </inertial>
  </link>
  <joint name="joint2" type="revolute">
    <parent link="link2"/>
    <child link="link3"/>
    <origin rpy="0.0 0.0 0.0" xyz="0.0 0.0 0.0595"/>
    <axis xyz="0 1 0"/>
    <limit effort="1" lower="-1.790707812546182" upper="1.5707963267948966" velocity="4.8"/>
    <dynamics damping="0.1"/>
  </joint>
  <link name="link3">
    <visual>
      <origin rpy="0.0 0.0 0.0" xyz="0.0 0.0 0.0"/>
      <geometry>
        <mesh filename="http://{{.Host}}:{{env "FOXGLOVE_PORT"}}/ros2_ws/install/open_manipulator_x_description/share/open_manipulator_x_description/meshes/link3.stl" scale="0.001 0.001 0.001"/>
      </geometry>
      <material name="grey"/>
    </visual>
    <collision>
      <origin rpy="0.0 0.0 0.0" xyz="0.0 0.0 0.0"/>
      <geometry>
        <mesh filename="http://{{.Host}}:{{env "FOXGLOVE_PORT"}}/ros2_ws/install/open_manipulator_x_description/share/open_manipulator_x_description/meshes/link3.stl" scale="0.001 0.001 0.001"/>
      </geometry>
    </collision>
    <inertial>
      <origin xyz="1.0308393e-02 3.7743363e-04 1.0170197e-01"/>
      <mass value="1.3850917e-01"/>
      <inertia ixx="3.3055381e-04" ixy="-9.7940978e-08" ixz="-3.8505711e-05" iyy="3.4290447e-04" iyz="-1.5717516e-06" izz="6.0346498e-05"/>
    </inertial>
  </link>
  <joint name="joint3" type="revolute">
    <parent link="link3"/>
    <child link="link4"/>
    <origin rpy="0.0 0.0 0.0" xyz="0.024 0.0 0.128"/>
    <axis xyz="0 1 0"/>
    <limit effort="1" lower="-1.5707963267948966" upper="1.382300767579509" velocity="4.8"/>
    <dynamics damping="0.1"/>
  </joint>
  <link name="link4">
    <visual>
      <origin rpy="0.0 0.0 0.0" xyz="0.0 0.0 0.0"/>
      <geometry>
        <mesh filename="http://{{.Host}}:{{env "FOXGLOVE_PORT"}}/ros2_ws/install/open_manipulator_x_description/share/open_manipulator_x_description/meshes/link4.stl" scale="0.001 0.001 0.001"/>
      </geometry>
      <material name="grey"/>
    </visual>
    <collision>
      <origin rpy="0.0 0.0 0.0" xyz="0.0 0.0 0.0"/>
      <geometry>
        <mesh filename="http://{{.Host}}:{{env "FOXGLOVE_PORT"}}/ros2_ws/install/open_manipulator_x_description/share/open_manipulator_x_description/meshes/link4.stl" scale="0.001 0.001 0.001"/>
      </geometry>
    </collision>
    <inertial>
      <origin xyz="9.0909590e-02 3.8929816e-04 2.2413279e-04"/>
      <mass value="1.3274562e-01"/>
      <inertia ixx="3.0654178e-05" ixy="-1.2764155e-06" ixz="-2.6874417e-07" iyy="2.4230292e-04" iyz="1.1559550e-08" izz="2.5155057e-04"/>
    </inertial>
  </link>
  <joint name="joint4" type="revolute">
    <parent link="link4"/>
    <child link="link5"/>
    <origin rpy="0.0 0.0 0.0" xyz="0.124 0.0 0.0"/>
    <axis xyz="0 1 0"/>
    <limit effort="1" lower="-1.7278759594743864" upper="2.0420352248333655" velocity="4.8"/>
    <dynamics damping="0.1"/>
  </joint>
  <link name="link5">
    <visual>
      <origin rpy="0.0 0.0 0.0" xyz="0.0 0.0 0.0"/>
      <geometry>
        <mesh filename="http://{{.Host}}:{{env "FOXGLOVE_PORT"}}/ros2_ws/install/open_manipulator_x_description/share/open_manipulator_x_description/meshes/link5.stl" scale="0.001 0.001 0.001"/>
      </geometry>
      <material name="grey"/>
    </visual>
    <collision>
      <origin rpy="0.0 0.0 0.0" xyz="0.0 0.0 0.0"/>
      <geometry>
        <mesh filename="http://{{.Host}}:{{env "FOXGLOVE_PORT"}}/ros2_ws/install/open_manipulator_x_description/share/open_manipulator_x_description/meshes/link5.stl" scale="0.001 0.001 0.001"/>
      </geometry>
    </collision>
    <inertial>
      <origin xyz="4.4206755e-02 3.6839985e-07 8.9142216e-03"/>
      <mass value="1.4327573e-01"/>
      <inertia ixx="8.0870749e-05" ixy="0.0" ixz="-1.0157896e-06" iyy="7.5980465e-05" iyz="0.0" izz="9.3127351e-05"/>
    </inertial>
  </link>
  <joint name="gripper_left_joint" type="prismatic">
    <parent link="link5"/>
    <child link="gripper_left_link"/>
    <origin rpy="0.0 0.0 0.0" xyz="0.0817 0.021 0.0"/>
    <axis xyz="0 1 0"/>
    <limit effort="1" lower="-0.010" upper="0.019" velocity="4.8"/>
    <dynamics damping="0.1"/>
  </joint>
  <link name="gripper_left_link">
    <visual>
      <origin rpy="0.0 0.0 0.0" xyz="0.0 0.0 0.0"/>
      <geometry>
        <mesh filename="http://{{.Host}}:{{env "FOXGLOVE_PORT"}}/ros2_ws/install/open_manipulator_x_description/share/open_manipulator_x_description/meshes/gripper_left_palm.stl" scale="0.001 0.001 0.001"/>
      </geometry>
      <material name="grey"/>
    </visual>
    <collision>
      <origin rpy="0.0 0.0 0.0" xyz="0.0 0.0 0.0"/>
      <geometry>
        <mesh filename="http://{{.Host}}:{{env "FOXGLOVE_PORT"}}/ros2_ws/install/open_manipulator_x_description/share/open_manipulator_x_description/meshes/gripper_left_palm.stl" scale="0.001 0.001 0.001"/>
      </geometry>
    </collision>
    <inertial>
      <origin xyz="0.0 0.0 0.0"/>
      <mass value="1.0e-03"/>
      <inertia ixx="1.0e-06" ixy="0.0" ixz="0.0" iyy="1.0e-06" iyz="0.0" izz="1.0e-06"/>
    </inertial>
  </link>
  <joint name="gripper_right_joint" type="prismatic">
    <parent link="link5"/>
    <child link="gripper_right_link"/>
    <origin rpy="0.0 0.0 0.0" xyz="0.0817 -0.021 0.0"/>
    <axis xyz="0 -1 0"/>
    <limit effort="1" lower="-0.010" upper="0.019" velocity="4.8"/>
    <mimic joint="gripper_left_joint" multiplier="1"/>
    <dynamics damping="0.1"/>
  </joint>
  <link name="gripper_right_link">
    <visual>
      <origin rpy="0.0 0.0 0.0" xyz="0.0 0.0 0.0"/>
      <geometry>
        <mesh filename="http://{{.Host}}:{{env "FOXGLOVE_PORT"}}/ros2_ws/install/open_manipulator_x_description/share/open_manipulator_x_description/meshes/gripper_right_palm.stl" scale="0.001 0.001 0.001"/>
      </geometry>
      <material name="grey"/>
    </visual>
    <collision>
      <origin rpy="0.0 0.0 0.0" xyz="0.0 0.0 0.0"/>
      <geometry>
        <mesh filename="http://{{.Host}}:{{env "FOXGLOVE_PORT"}}/ros2_ws/install/open_manipulator_x_description/share/open_manipulator_x_description/meshes/gripper_right_palm.stl" scale="0.001 0.001 0.001"/>
      </geometry>
    </collision>
    <inertial>
      <origin xyz="0 0 0"/>
      <mass value="1.0e-03"/>
      <inertia ixx="1.0e-06" ixy="0.0" ixz="0.0" iyy="1.0e-06" iyz="0.0" izz="1.0e-06"/>
    </inertial>
  </link>
  <joint name="end_effector_joint" type="fixed">
    <parent link="link5"/>
    <child link="end_effector_link"/>
    <origin rpy="0.0 0.0 0.0" xyz="0.126 0.0 0.0"/>
  </joint>
  <link name="end_effector_link"/>
  <ros2_control name="manipulator" type="system">
    <hardware>
      <plugin>open_manipulator_x_hardware/OpenManipulatorXSystem</plugin>
      <param name="usb_port">/dev/ttyUSB0</param>
      <param name="baud_rate">1000000</param>
      <param name="control_period">0.1</param>
      <param name="manipulator_joint_profile_acceleration">200</param>
      <param name="manipulator_joint_profile_velocity">500</param>
      <param name="gripper_joint_profile_acceleration">500</param>
      <param name="gripper_joint_profile_velocity">1000</param>
    </hardware>
    <joint name="joint1">
      <command_interface name="position">
        <param name="min">-2.356</param>
        <param name="max">5.934</param>
      </command_interface>
      <state_interface name="position"/>
      <state_interface name="velocity"/>
    </joint>
    <joint name="joint2">
      <command_interface name="position">
        <param name="min">-1.790707812546182</param>
        <param name="max">1.5707963267948966</param>
      </command_interface>
      <state_interface name="position"/>
      <state_interface name="velocity"/>
    </joint>
    <joint name="joint3">
      <command_interface name="position">
        <param name="min">-0.9424777960769379</param>
        <param name="max">1.382300767579509</param>
      </command_interface>
      <state_interface name="position"/>
      <state_interface name="velocity"/>
    </joint>
    <joint name="joint4">
      <command_interface name="position">
        <param name="min">-1.790707812546182</param>
        <param name="max">2.0420352248333655</param>
      </command_interface>
      <state_interface name="position"/>
      <state_interface name="velocity"/>
    </joint>
    <joint name="gripper_left_joint">
      <command_interface name="position">
        <param name="min">-0.010</param>
        <param name="max">0.019</param>
      </command_interface>
      <state_interface name="position"/>
      <state_interface name="velocity"/>
    </joint>
  </ros2_control>
</robot>
